Workbook

Sheet ReadMe
B2: Telecom Service Ticket Analytics — Data Model
B3: Sheets in this workbook
B4: Dim_Plan | C4: 15 mobile plans — Prepaid, Postpaid, and Corporate tiers with target customer segment
B5: Dim_Region | C5: 15 regions across Bangladesh divisions (Dhaka, Chattogram, Khulna, Rajshahi, Sylhet, Barishal, Rangpur, Mymensingh), urban/rural area type
B6: Dim_ServiceType | C6: 15 complaint categories (Network, Billing, SIM, Data Service, Value Added Service, Roaming, Customer Service) each with its own SLA_Hours target
B7: Dim_Agent | C7: 15 support agents across Network/Billing/Technical/Customer Care/SIM & Porting teams
B8: Dim_Date | C8: Calendar table, FY2025 (Jan 1 - Dec 31), 365 rows — one per day
B9: Fact_Ticket | C9: 1,000 service tickets spanning the full lifecycle: Raised -> Assigned -> Resolved -> Closed. Includes in-flight (pending) tickets as of the snapshot date-time above.
B11: Why some fact rows have blank date-times
B12: 5% of rows (50) are stuck unassigned — only RaisedDateTime is filled. TicketStatus = 'Open (Unassigned)'.
B13: 10% of rows (100) are assigned but not yet resolved — AssignedDateTime exists, ResolvedDateTime and ClosedDateTime are blank. TicketStatus = 'In Progress'.
B14: 85% of rows (850) are fully closed. TicketStatus = 'Closed'.
B16: Columns built in for this kind of analysis
B17: Pending / SLA logic | C17: TicketStatus (Open/In Progress/Resolved/Closed) and SLABreachFlag (actual resolution time vs. that ServiceType's SLA_Hours in Dim_ServiceType).
B18: Bottleneck across stages | C18: AssignmentDelayHours, ResolutionTimeHours, TotalCycleTimeHours — each stage timed separately in hours (telecom SLAs are hour-based, not day-based).
B19: Comparative analysis | C19: PlanID / RegionID / ServiceTypeID / AgentID keys let you pivot the same measures by plan, region, complaint type, or agent/team.
B20: Operational decision making | C20: CustomerSatisfactionScore and ReopenedFlag translate resolution speed into a customer-experience and rework signal.

Sheet Dim_Plan
A1: PlanID | B1: PlanName | C1: PlanType | D1: MonthlyFeeBDT | E1: DataAllowanceGB | F1: VoiceMinutes | G1: TargetSegment
A2: 1 | B2: Prepaid Basic | C2: Prepaid | D2: 99 | E2: 2 | F2: 200 | G2: Mass Market
A3: 2 | B3: Prepaid Value | C3: Prepaid | D3: 199 | E3: 6 | F3: 500 | G3: Mass Market
A4: 3 | B4: Prepaid Power | C4: Prepaid | D4: 349 | E4: 15 | F4: 1000 | G4: Youth
A5: 4 | B5: Prepaid Unlimited Lite | C5: Prepaid | D5: 499 | E5: 25 | F5: 2000 | G5: Youth
A6: 5 | B6: Postpaid Smart | C6: Postpaid | D6: 599 | E6: 20 | F6: 1500 | G6: Professional
A7: 6 | B7: Postpaid Premium | C7: Postpaid | D7: 999 | E7: 40 | F7: 3000 | G7: Professional
A8: 7 | B8: Postpaid Family | C8: Postpaid | D8: 1499 | E8: 60 | F8: 5000 | G8: Family
A9: 8 | B9: Postpaid Executive | C9: Postpaid | D9: 1999 | E9: 80 | F9: 7000 | G9: Professional
A10: 9 | B10: Corporate Standard | C10: Corporate | D10: 799 | E10: 30 | F10: 3000 | G10: SME
A11: 10 | B11: Corporate Plus | C11: Corporate | D11: 1499 | E11: 60 | F11: 6000 | G11: SME
A12: 11 | B12: Corporate Enterprise | C12: Corporate | D12: 2999 | E12: 150 | F12: 15000 | G12: Enterprise
A13: 12 | B13: Student Saver | C13: Prepaid | D13: 149 | E13: 8 | F13: 600 | G13: Student
... A16: 15 | B16: Roaming Traveller Pack | C16: Prepaid | D16: 1999 | E16: 5 | F16: 500 | G16: Traveller

Sheet Dim_Region
A1: RegionID | B1: RegionName | C1: Division | D1: AreaType | E1: PopulationDensity
A2: 1 | B2: Dhaka Metro | C2: Dhaka | D2: Urban | E2: Very High
A3: 2 | B3: Dhaka North | C3: Dhaka | D3: Urban | E3: High
A4: 3 | B4: Gazipur | C4: Dhaka | D4: Urban | E4: High
A5: 4 | B5: Narayanganj | C5: Dhaka | D5: Urban | E5: High
A6: 5 | B6: Chattogram Metro | C6: Chattogram | D6: Urban | E6: Very High
A7: 6 | B7: Cox's Bazar | C7: Chattogram | D7: Rural | E7: Low
A8: 7 | B8: Cumilla | C8: Chattogram | D8: Urban | E8: Medium
A9: 8 | B9: Khulna | C9: Khulna | D9: Urban | E9: Medium
A10: 9 | B10: Jashore | C10: Khulna | D10: Rural | E10: Low
A11: 10 | B11: Rajshahi | C11: Rajshahi | D11: Urban | E11: Medium
A12: 11 | B12: Bogura | C12: Rajshahi | D12: Rural | E12: Low
A13: 12 | B13: Sylhet | C13: Sylhet | D13: Urban | E13: Medium
... A16: 15 | B16: Mymensingh | C16: Mymensingh | D16: Urban | E16: Medium

Sheet Dim_ServiceType
A1: ServiceTypeID | B1: CategoryName | C1: SubCategory | D1: Priority | E1: SLA_Hours
A2: 1 | B2: Network | C2: Call Drop | D2: High | E2: 4
A3: 2 | B3: Network | C3: No Signal / Coverage | D3: High | E3: 6
A4: 3 | B4: Network | C4: Slow Data Speed | D4: Medium | E4: 8
A5: 4 | B5: Billing | C5: Incorrect Charge | D5: Medium | E5: 24
A6: 5 | B6: Billing | C6: Balance Deduction Dispute | D6: High | E6: 12
A7: 6 | B7: Billing | C7: Refund Request | D7: Medium | E7: 48
A8: 7 | B8: SIM | C8: SIM Replacement | D8: Medium | E8: 24
A9: 8 | B9: SIM | C9: SIM Activation Issue | D9: High | E9: 6
A10: 9 | B10: SIM | C10: Number Porting (MNP) | D10: Medium | E10: 72
A11: 10 | B11: Data Service | C11: Internet Not Working | D11: High | E11: 6
A12: 11 | B12: Data Service | C12: APN Configuration | D12: Low | E12: 12
A13: 12 | B13: Value Added Service | C13: Unwanted Subscription | D13: Low | E13: 24
... A16: 15 | B16: Customer Service | C16: General Inquiry | D16: Low | E16: 24

Sheet Dim_Agent
A1: AgentID | B1: AgentName | C1: Team | D1: Shift | E1: ExperienceYears | F1: AgentRating
A2: 1 | B2: Tanvir Ahmed | C2: Network Support | D2: Day | E2: 5 | F2: 4.6
A3: 2 | B3: Nusrat Jahan | C3: Billing Support | D3: Day | E3: 3 | F3: 4.4
A4: 3 | B4: Kamal Hossain | C4: Customer Care | D4: Day | E4: 6 | F4: 4.7
A5: 4 | B5: Farida Yasmin | C5: Technical Support | D5: Night | E5: 4 | F5: 4.3
A6: 5 | B6: Rafiqul Islam | C6: Network Support | D6: Night | E6: 7 | F6: 4.5
A7: 6 | B7: Mahmuda Begum | C7: Billing Support | D7: Day | E7: 2 | F7: 4.1
A8: 7 | B8: Abdul Karim | C8: SIM & Porting | D8: Day | E8: 5 | F8: 4.4
A9: 8 | B9: Jashim Uddin | C9: Technical Support | D9: Day | E9: 3 | F9: 4.2
A10: 9 | B10: Ruma Akter | C10: Customer Care | D10: Night | E10: 4 | F10: 4.6
A11: 10 | B11: Shamsul Alam | C11: Network Support | D11: Day | E11: 8 | F11: 4.8
A12: 11 | B12: Shirin Sultana | C12: Billing Support | D12: Night | E12: 3 | F12: 4
A13: 12 | B13: Anisur Rahman | C13: SIM & Porting | D13: Night | E13: 5 | F13: 4.3
... A16: 15 | B16: Sultana Razia | C16: Network Support | D16: Night | E16: 4 | F16: 4.4

Sheet Dim_Date
A1: DateID | B1: Date | C1: Year | D1: Quarter | E1: Month | F1: MonthName | G1: WeekOfYear | H1: DayOfWeek | I1: IsWeekend
A2: 1 | B2: 45658 | C2: 2025 | D2: Q1 | E2: 1 | F2: January | G2: 1 | H2: Wednesday | I2: 0
A3: 2 | B3: 45659 | C3: 2025 | D3: Q1 | E3: 1 | F3: January | G3: 1 | H3: Thursday | I3: 0
A4: 3 | B4: 45660 | C4: 2025 | D4: Q1 | E4: 1 | F4: January | G4: 1 | H4: Friday | I4: 0
A5: 4 | B5: 45661 | C5: 2025 | D5: Q1 | E5: 1 | F5: January | G5: 1 | H5: Saturday | I5: 1
A6: 5 | B6: 45662 | C6: 2025 | D6: Q1 | E6: 1 | F6: January | G6: 1 | H6: Sunday | I6: 1
A7: 6 | B7: 45663 | C7: 2025 | D7: Q1 | E7: 1 | F7: January | G7: 2 | H7: Monday | I7: 0
A8: 7 | B8: 45664 | C8: 2025 | D8: Q1 | E8: 1 | F8: January | G8: 2 | H8: Tuesday | I8: 0
A9: 8 | B9: 45665 | C9: 2025 | D9: Q1 | E9: 1 | F9: January | G9: 2 | H9: Wednesday | I9: 0
A10: 9 | B10: 45666 | C10: 2025 | D10: Q1 | E10: 1 | F10: January | G10: 2 | H10: Thursday | I10: 0
A11: 10 | B11: 45667 | C11: 2025 | D11: Q1 | E11: 1 | F11: January | G11: 2 | H11: Friday | I11: 0
A12: 11 | B12: 45668 | C12: 2025 | D12: Q1 | E12: 1 | F12: January | G12: 2 | H12: Saturday | I12: 1
A13: 12 | B13: 45669 | C13: 2025 | D13: Q1 | E13: 1 | F13: January | G13: 2 | H13: Sunday | I13: 1
... A366: 365 | B366: 46022 | C366: 2025 | D366: Q4 | E366: 12 | F366: December | G366: 53 | H366: Wednesday | I366: 0

Sheet Fact_Ticket
A1: TicketID | B1: TicketNumber | C1: PlanID | D1: RegionID | E1: ServiceTypeID | F1: AgentID | G1: RaisedDateTime | H1: AssignedDateTime | I1: ResolvedDateTime | J1: ClosedDateTime | K1: Channel | L1: AssignmentDelayHours | M1: ResolutionTimeHours | N1: TotalCycleTimeHours | O1: SLABreachFlag | P1: TicketStatus | Q1: CustomerSatisfactionScore | R1: ReopenedFlag
A2: 1 | B2: TCK-2025-00001 | C2: 12 | D2: 1 | E2: 13 | F2: 12 | G2: 45850.533 | H2: 45850.616 | I2: 45850.962 | J2: 45850.983 | K2: Social Media | L2: =IF(ISBLANK(H2),"",(H2-G2)*24) -> 2 | M2: =IF(ISBLANK(I2),"",(I2-H2)*24) -> 8.3 | N2: =IF(ISBLANK(J2),"",(J2-G2)*24) -> 10.8 | O2: =IF(ISBLANK(I2),"N/A",IF(((I2-H2)*24)>INDEX(Dim_ServiceType!$E$2:$E$16,MATCH(E2,Dim_ServiceType!$A$2:$A$16,0)),"Yes","No")) -> No | P2: =IF(ISBLANK(H2),"Open (Unassigned)",IF(ISBLANK(I2),"In Progress",IF(ISBLANK(J2),"Resolved (Pending Closure)","Closed"))) -> Closed | Q2: 4 | R2: Yes
A3: 2 | B3: TCK-2025-00002 | C3: 3 | D3: 14 | E3: 9 | F3: 9 | G3: 45870.258 | H3: 45870.424 | I3: 45872.07 | J3: 45872.153 | K3: Website | L3: =IF(ISBLANK(H3),"",(H3-G3)*24) -> 4 | M3: =IF(ISBLANK(I3),"",(I3-H3)*24) -> 39.5 | N3: =IF(ISBLANK(J3),"",(J3-G3)*24) -> 45.5 | O3: =IF(ISBLANK(I3),"N/A",IF(((I3-H3)*24)>INDEX(Dim_ServiceType!$E$2:$E$16,MATCH(E3,Dim_ServiceType!$A$2:$A$16,0)),"Yes","No")) -> No | P3: =IF(ISBLANK(H3),"Open (Unassigned)",IF(ISBLANK(I3),"In Progress",IF(ISBLANK(J3),"Resolved (Pending Closure)","Closed"))) -> Closed | Q3: 2 | R3: No
A4: 3 | B4: TCK-2025-00003 | C4: 5 | D4: 4 | E4: 15 | F4: 8 | G4: 45913.034 | H4: 45913.284 | I4: 45913.909 | J4: 45914.159 | K4: Mobile App | L4: =IF(ISBLANK(H4),"",(H4-G4)*24) -> 6 | M4: =IF(ISBLANK(I4),"",(I4-H4)*24) -> 15 | N4: =IF(ISBLANK(J4),"",(J4-G4)*24) -> 27 | O4: =IF(ISBLANK(I4),"N/A",IF(((I4-H4)*24)>INDEX(Dim_ServiceType!$E$2:$E$16,MATCH(E4,Dim_ServiceType!$A$2:$A$16,0)),"Yes","No")) -> No | P4: =IF(ISBLANK(H4),"Open (Unassigned)",IF(ISBLANK(I4),"In Progress",IF(ISBLANK(J4),"Resolved (Pending Closure)","Closed"))) -> Closed | Q4: 4 | R4: No
A5: 4 | B5: TCK-2025-00004 | C5: 13 | D5: 13 | E5: 14 | F5: 1 | G5: 45879.035 | H5: 45879.201 | I5: 45879.614 | J5: 45879.781 | K5: Call Center | L5: =IF(ISBLANK(H5),"",(H5-G5)*24) -> 4 | M5: =IF(ISBLANK(I5),"",(I5-H5)*24) -> 9.9 | N5: =IF(ISBLANK(J5),"",(J5-G5)*24) -> 17.9 | O5: =IF(ISBLANK(I5),"N/A",IF(((I5-H5)*24)>INDEX(Dim_ServiceType!$E$2:$E$16,MATCH(E5,Dim_ServiceType!$A$2:$A$16,0)),"Yes","No")) -> Yes | P5: =IF(ISBLANK(H5),"Open (Unassigned)",IF(ISBLANK(I5),"In Progress",IF(ISBLANK(J5),"Resolved (Pending Closure)","Closed"))) -> Closed | Q5: 5 | R5: No
A6: 5 | B6: TCK-2025-00005 | C6: 13 | D6: 5 | E6: 11 | F6: 15 | G6: 45707.687 | H6: 45707.812 | I6: 45708.362 | J6: 45709.362 | K6: Call Center | L6: =IF(ISBLANK(H6),"",(H6-G6)*24) -> 3 | M6: =IF(ISBLANK(I6),"",(I6-H6)*24) -> 13.2 | N6: =IF(ISBLANK(J6),"",(J6-G6)*24) -> 40.2 | O6: =IF(ISBLANK(I6),"N/A",IF(((I6-H6)*24)>INDEX(Dim_ServiceType!$E$2:$E$16,MATCH(E6,Dim_ServiceType!$A$2:$A$16,0)),"Yes","No")) -> Yes | P6: =IF(ISBLANK(H6),"Open (Unassigned)",IF(ISBLANK(I6),"In Progress",IF(ISBLANK(J6),"Resolved (Pending Closure)","Closed"))) -> Closed | Q6: 5 | R6: No
A7: 6 | B7: TCK-2025-00006 | C7: 8 | D7: 13 | E7: 7 | F7: 9 | G7: 45829.529 | H7: 45829.695 | I7: 45832.916 | J7: 45832.958 | K7: Mobile App | L7: =IF(ISBLANK(H7),"",(H7-G7)*24) -> 4 | M7: =IF(ISBLANK(I7),"",(I7-H7)*24) -> 77.3 | N7: =IF(ISBLANK(J7),"",(J7-G7)*24) -> 82.3 | O7: =IF(ISBLANK(I7),"N/A",IF(((I7-H7)*24)>INDEX(Dim_ServiceType!$E$2:$E$16,MATCH(E7,Dim_ServiceType!$A$2:$A$16,0)),"Yes","No")) -> Yes | P7: =IF(ISBLANK(H7),"Open (Unassigned)",IF(ISBLANK(I7),"In Progress",IF(ISBLANK(J7),"Resolved (Pending Closure)","Closed"))) -> Closed | Q7: 4 | R7: No
A8: 7 | B8: TCK-2025-00007 | C8: 10 | D8: 10 | E8: 14 | F8: 3 | G8: 45860.608 | H8: 45860.774 | I8: 45862.408 | J8: 45862.491 | K8: Website | L8: =IF(ISBLANK(H8),"",(H8-G8)*24) -> 4 | M8: =IF(ISBLANK(I8),"",(I8-H8)*24) -> 39.2 | N8: =IF(ISBLANK(J8),"",(J8-G8)*24) -> 45.2 | O8: =IF(ISBLANK(I8),"N/A",IF(((I8-H8)*24)>INDEX(Dim_ServiceType!$E$2:$E$16,MATCH(E8,Dim_ServiceType!$A$2:$A$16,0)),"Yes","No")) -> Yes | P8: =IF(ISBLANK(H8),"Open (Unassigned)",IF(ISBLANK(I8),"In Progress",IF(ISBLANK(J8),"Resolved (Pending Closure)","Closed"))) -> Closed | Q8: 3 | R8: Yes
A9: 8 | B9: TCK-2025-00008 | C9: 13 | D9: 1 | E9: 6 | F9: 9 | G9: 45882.756 | H9: 45883.506 | I9: 45885.789 | J9: 45886.039 | K9: Social Media | L9: =IF(ISBLANK(H9),"",(H9-G9)*24) -> 18 | M9: =IF(ISBLANK(I9),"",(I9-H9)*24) -> 54.8 | N9: =IF(ISBLANK(J9),"",(J9-G9)*24) -> 78.8 | O9: =IF(ISBLANK(I9),"N/A",IF(((I9-H9)*24)>INDEX(Dim_ServiceType!$E$2:$E$16,MATCH(E9,Dim_ServiceType!$A$2:$A$16,0)),"Yes","No")) -> Yes | P9: =IF(ISBLANK(H9),"Open (Unassigned)",IF(ISBLANK(I9),"In Progress",IF(ISBLANK(J9),"Resolved (Pending Closure)","Closed"))) -> Closed | Q9: 3 | R9: No
A10: 9 | B10: TCK-2025-00009 | C10: 6 | D10: 8 | E10: 4 | F10: 8 | G10: 45682.48 | H10: 45682.5 | I10: 45683.109 | J10: 45683.192 | K10: Website | L10: =IF(ISBLANK(H10),"",(H10-G10)*24) -> 0.5 | M10: =IF(ISBLANK(I10),"",(I10-H10)*24) -> 14.6 | N10: =IF(ISBLANK(J10),"",(J10-G10)*24) -> 17.1 | O10: =IF(ISBLANK(I10),"N/A",IF(((I10-H10)*24)>INDEX(Dim_ServiceType!$E$2:$E$16,MATCH(E10,Dim_ServiceType!$A$2:$A$16,0)),"Yes","No")) -> No | P10: =IF(ISBLANK(H10),"Open (Unassigned)",IF(ISBLANK(I10),"In Progress",IF(ISBLANK(J10),"Resolved (Pending Closure)","Closed"))) -> Closed | Q10: 4 | R10: No
A11: 10 | B11: TCK-2025-00010 | C11: 12 | D11: 13 | E11: 13 | F11: 5 | G11: 45933.016 | H11: 45934.016 | I11: 45934.966 | J11: 45935.466 | K11: Retail Store | L11: =IF(ISBLANK(H11),"",(H11-G11)*24) -> 24 | M11: =IF(ISBLANK(I11),"",(I11-H11)*24) -> 22.8 | N11: =IF(ISBLANK(J11),"",(J11-G11)*24) -> 58.8 | O11: =IF(ISBLANK(I11),"N/A",IF(((I11-H11)*24)>INDEX(Dim_ServiceType!$E$2:$E$16,MATCH(E11,Dim_ServiceType!$A$2:$A$16,0)),"Yes","No")) -> No | P11: =IF(ISBLANK(H11),"Open (Unassigned)",IF(ISBLANK(I11),"In Progress",IF(ISBLANK(J11),"Resolved (Pending Closure)","Closed"))) -> Closed | Q11: 5 | R11: No
A12: 11 | B12: TCK-2025-00011 | C12: 7 | D12: 4 | E12: 7 | F12: 15 | G12: 45749.414 | H12: 45749.914 | I12: 45754.26 | J12: 45754.427 | K12: Social Media | L12: =IF(ISBLANK(H12),"",(H12-G12)*24) -> 12 | M12: =IF(ISBLANK(I12),"",(I12-H12)*24) -> 104.3 | N12: =IF(ISBLANK(J12),"",(J12-G12)*24) -> 120.3 | O12: =IF(ISBLANK(I12),"N/A",IF(((I12-H12)*24)>INDEX(Dim_ServiceType!$E$2:$E$16,MATCH(E12,Dim_ServiceType!$A$2:$A$16,0)),"Yes","No")) -> Yes | P12: =IF(ISBLANK(H12),"Open (Unassigned)",IF(ISBLANK(I12),"In Progress",IF(ISBLANK(J12),"Resolved (Pending Closure)","Closed"))) -> Closed | Q12: 3 | R12: No
A13: 12 | B13: TCK-2025-00012 | C13: 6 | D13: 10 | E13: 6 | F13: 7 | G13: 45899.632 | H13: 45899.882 | I13: 45900.498 | J13: 45900.519 | K13: Call Center | L13: =IF(ISBLANK(H13),"",(H13-G13)*24) -> 6 | M13: =IF(ISBLANK(I13),"",(I13-H13)*24) -> 14.8 | N13: =IF(ISBLANK(J13),"",(J13-G13)*24) -> 21.3 | O13: =IF(ISBLANK(I13),"N/A",IF(((I13-H13)*24)>INDEX(Dim_ServiceType!$E$2:$E$16,MATCH(E13,Dim_ServiceType!$A$2:$A$16,0)),"Yes","No")) -> No | P13: =IF(ISBLANK(H13),"Open (Unassigned)",IF(ISBLANK(I13),"In Progress",IF(ISBLANK(J13),"Resolved (Pending Closure)","Closed"))) -> Closed | Q13: 3 | R13: Yes
... A27: 26 | B27: TCK-2025-00026 | C27: 6 | D27: 7 | E27: 13 | F27: 12 | G27: 45975.778 | H27: 45975.82 | I27: 45976.466 | J27: 45976.507 | K27: Mobile App | L27: =IF(ISBLANK(H27),"",(H27-G27)*24) -> 1 | M27: =IF(ISBLANK(I27),"",(I27-H27)*24) -> 15.5 | N27: =IF(ISBLANK(J27),"",(J27-G27)*24) -> 17.5 | O27: =IF(ISBLANK(I27),"N/A",IF(((I27-H27)*24)>INDEX(Dim_ServiceType!$E$2:$E$16,MATCH(E27,Dim_ServiceType!$A$2:$A$16,0)),"Yes","No")) -> No | P27: =IF(ISBLANK(H27),"Open (Unassigned)",IF(ISBLANK(I27),"In Progress",IF(ISBLANK(J27),"Resolved (Pending Closure)","Closed"))) -> Closed | Q27: 5 | R27: No
A28: 27 | B28: TCK-2025-00027 | C28: 12 | D28: 12 | E28: 7 | F28: 5 | G28: 46002.214 | K28: Social Media | L28: =IF(ISBLANK(H28),"",(H28-G28)*24) | M28: =IF(ISBLANK(I28),"",(I28-H28)*24) | N28: =IF(ISBLANK(J28),"",(J28-G28)*24) | O28: =IF(ISBLANK(I28),"N/A",IF(((I28-H28)*24)>INDEX(Dim_ServiceType!$E$2:$E$16,MATCH(E28,Dim_ServiceType!$A$2:$A$16,0)),"Yes","No")) -> N/A | P28: =IF(ISBLANK(H28),"Open (Unassigned)",IF(ISBLANK(I28),"In Progress",IF(ISBLANK(J28),"Resolved (Pending Closure)","Closed"))) -> Open (Unassigned)
A29: 28 | B29: TCK-2025-00028 | C29: 7 | D29: 13 | E29: 2 | F29: 2 | G29: 45872.685 | H29: 45872.705 | I29: 45873.026 | J29: 45873.193 | K29: Mobile App | L29: =IF(ISBLANK(H29),"",(H29-G29)*24) -> 0.5 | M29: =IF(ISBLANK(I29),"",(I29-H29)*24) -> 7.7 | N29: =IF(ISBLANK(J29),"",(J29-G29)*24) -> 12.2 | O29: =IF(ISBLANK(I29),"N/A",IF(((I29-H29)*24)>INDEX(Dim_ServiceType!$E$2:$E$16,MATCH(E29,Dim_ServiceType!$A$2:$A$16,0)),"Yes","No")) -> Yes | P29: =IF(ISBLANK(H29),"Open (Unassigned)",IF(ISBLANK(I29),"In Progress",IF(ISBLANK(J29),"Resolved (Pending Closure)","Closed"))) -> Closed | Q29: 2 | R29: No
A30: 29 | B30: TCK-2025-00029 | C30: 8 | D30: 1 | E30: 2 | F30: 13 | G30: 45929.951 | H30: 45929.993 | I30: 45930.318 | J30: 45930.339 | K30: Website | L30: =IF(ISBLANK(H30),"",(H30-G30)*24) -> 1 | M30: =IF(ISBLANK(I30),"",(I30-H30)*24) -> 7.8 | N30: =IF(ISBLANK(J30),"",(J30-G30)*24) -> 9.3 | O30: =IF(ISBLANK(I30),"N/A",IF(((I30-H30)*24)>INDEX(Dim_ServiceType!$E$2:$E$16,MATCH(E30,Dim_ServiceType!$A$2:$A$16,0)),"Yes","No")) -> Yes | P30: =IF(ISBLANK(H30),"Open (Unassigned)",IF(ISBLANK(I30),"In Progress",IF(ISBLANK(J30),"Resolved (Pending Closure)","Closed"))) -> Closed | Q30: 4 | R30: No
A31: 30 | B31: TCK-2025-00030 | C31: 8 | D31: 5 | E31: 12 | F31: 3 | G31: 45668.455 | H31: 45668.621 | I31: 45669.609 | J31: 45669.692 | K31: Call Center | L31: =IF(ISBLANK(H31),"",(H31-G31)*24) -> 4 | M31: =IF(ISBLANK(I31),"",(I31-H31)*24) -> 23.7 | N31: =IF(ISBLANK(J31),"",(J31-G31)*24) -> 29.7 | O31: =IF(ISBLANK(I31),"N/A",IF(((I31-H31)*24)>INDEX(Dim_ServiceType!$E$2:$E$16,MATCH(E31,Dim_ServiceType!$A$2:$A$16,0)),"Yes","No")) -> No | P31: =IF(ISBLANK(H31),"Open (Unassigned)",IF(ISBLANK(I31),"In Progress",IF(ISBLANK(J31),"Resolved (Pending Closure)","Closed"))) -> Closed | Q31: 4 | R31: Yes
A32: 31 | B32: TCK-2025-00031 | C32: 13 | D32: 1 | E32: 3 | F32: 9 | G32: 45788.103 | H32: 45788.186 | K32: Retail Store | L32: =IF(ISBLANK(H32),"",(H32-G32)*24) -> 2 | M32: =IF(ISBLANK(I32),"",(I32-H32)*24) | N32: =IF(ISBLANK(J32),"",(J32-G32)*24) | O32: =IF(ISBLANK(I32),"N/A",IF(((I32-H32)*24)>INDEX(Dim_ServiceType!$E$2:$E$16,MATCH(E32,Dim_ServiceType!$A$2:$A$16,0)),"Yes","No")) -> N/A | P32: =IF(ISBLANK(H32),"Open (Unassigned)",IF(ISBLANK(I32),"In Progress",IF(ISBLANK(J32),"Resolved (Pending Closure)","Closed"))) -> In Progress
A33: 32 | B33: TCK-2025-00032 | C33: 15 | D33: 1 | E33: 4 | F33: 3 | G33: 46001.57 | K33: Social Media | L33: =IF(ISBLANK(H33),"",(H33-G33)*24) | M33: =IF(ISBLANK(I33),"",(I33-H33)*24) | N33: =IF(ISBLANK(J33),"",(J33-G33)*24) | O33: =IF(ISBLANK(I33),"N/A",IF(((I33-H33)*24)>INDEX(Dim_ServiceType!$E$2:$E$16,MATCH(E33,Dim_ServiceType!$A$2:$A$16,0)),"Yes","No")) -> N/A | P33: =IF(ISBLANK(H33),"Open (Unassigned)",IF(ISBLANK(I33),"In Progress",IF(ISBLANK(J33),"Resolved (Pending Closure)","Closed"))) -> Open (Unassigned)
A34: 33 | B34: TCK-2025-00033 | C34: 2 | D34: 10 | E34: 6 | F34: 7 | G34: 45841.829 | H34: 45841.954 | I34: 45843.554 | J34: 45843.596 | K34: Retail Store | L34: =IF(ISBLANK(H34),"",(H34-G34)*24) -> 3 | M34: =IF(ISBLANK(I34),"",(I34-H34)*24) -> 38.4 | N34: =IF(ISBLANK(J34),"",(J34-G34)*24) -> 42.4 | O34: =IF(ISBLANK(I34),"N/A",IF(((I34-H34)*24)>INDEX(Dim_ServiceType!$E$2:$E$16,MATCH(E34,Dim_ServiceType!$A$2:$A$16,0)),"Yes","No")) -> No | P34: =IF(ISBLANK(H34),"Open (Unassigned)",IF(ISBLANK(I34),"In Progress",IF(ISBLANK(J34),"Resolved (Pending Closure)","Closed"))) -> Closed | Q34: 2 | R34: Yes
A35: 34 | B35: TCK-2025-00034 | C35: 6 | D35: 4 | E35: 6 | F35: 6 | G35: 45850.008 | H35: 45850.091 | I35: 45856.466 | J35: 45857.466 | K35: Mobile App | L35: =IF(ISBLANK(H35),"",(H35-G35)*24) -> 2 | M35: =IF(ISBLANK(I35),"",(I35-H35)*24) -> 153 | N35: =IF(ISBLANK(J35),"",(J35-G35)*24) -> 179 | O35: =IF(ISBLANK(I35),"N/A",IF(((I35-H35)*24)>INDEX(Dim_ServiceType!$E$2:$E$16,MATCH(E35,Dim_ServiceType!$A$2:$A$16,0)),"Yes","No")) -> Yes | P35: =IF(ISBLANK(H35),"Open (Unassigned)",IF(ISBLANK(I35),"In Progress",IF(ISBLANK(J35),"Resolved (Pending Closure)","Closed"))) -> Closed | Q35: 2 | R35: No
A36: 35 | B36: TCK-2025-00035 | C36: 4 | D36: 3 | E36: 1 | F36: 5 | G36: 45728.763 | H36: 45729.513 | I36: 45729.563 | J36: 45729.646 | K36: Retail Store | L36: =IF(ISBLANK(H36),"",(H36-G36)*24) -> 18 | M36: =IF(ISBLANK(I36),"",(I36-H36)*24) -> 1.2 | N36: =IF(ISBLANK(J36),"",(J36-G36)*24) -> 21.2 | O36: =IF(ISBLANK(I36),"N/A",IF(((I36-H36)*24)>INDEX(Dim_ServiceType!$E$2:$E$16,MATCH(E36,Dim_ServiceType!$A$2:$A$16,0)),"Yes","No")) -> No | P36: =IF(ISBLANK(H36),"Open (Unassigned)",IF(ISBLANK(I36),"In Progress",IF(ISBLANK(J36),"Resolved (Pending Closure)","Closed"))) -> Closed | Q36: 2 | R36: No
A37: 36 | B37: TCK-2025-00036 | C37: 6 | D37: 2 | E37: 4 | F37: 7 | G37: 45897.967 | H37: 45897.987 | K37: Website | L37: =IF(ISBLANK(H37),"",(H37-G37)*24) -> 0.5 | M37: =IF(ISBLANK(I37),"",(I37-H37)*24) | N37: =IF(ISBLANK(J37),"",(J37-G37)*24) | O37: =IF(ISBLANK(I37),"N/A",IF(((I37-H37)*24)>INDEX(Dim_ServiceType!$E$2:$E$16,MATCH(E37,Dim_ServiceType!$A$2:$A$16,0)),"Yes","No")) -> N/A | P37: =IF(ISBLANK(H37),"Open (Unassigned)",IF(ISBLANK(I37),"In Progress",IF(ISBLANK(J37),"Resolved (Pending Closure)","Closed"))) -> In Progress
A38: 37 | B38: TCK-2025-00037 | C38: 12 | D38: 15 | E38: 3 | F38: 6 | G38: 45928.28 | H38: 45928.78 | I38: 45929.018 | J38: 45930.018 | K38: Mobile App | L38: =IF(ISBLANK(H38),"",(H38-G38)*24) -> 12 | M38: =IF(ISBLANK(I38),"",(I38-H38)*24) -> 5.7 | N38: =IF(ISBLANK(J38),"",(J38-G38)*24) -> 41.7 | O38: =IF(ISBLANK(I38),"N/A",IF(((I38-H38)*24)>INDEX(Dim_ServiceType!$E$2:$E$16,MATCH(E38,Dim_ServiceType!$A$2:$A$16,0)),"Yes","No")) -> No | P38: =IF(ISBLANK(H38),"Open (Unassigned)",IF(ISBLANK(I38),"In Progress",IF(ISBLANK(J38),"Resolved (Pending Closure)","Closed"))) -> Closed | Q38: 4 | R38: No
A39: 38 | B39: TCK-2025-00038 | C39: 11 | D39: 12 | E39: 3 | F39: 1 | G39: 45777.548 | H39: 45778.548 | I39: 45778.823 | J39: 45778.989 | K39: Mobile App | L39: =IF(ISBLANK(H39),"",(H39-G39)*24) -> 24 | M39: =IF(ISBLANK(I39),"",(I39-H39)*24) -> 6.6 | N39: =IF(ISBLANK(J39),"",(J39-G39)*24) -> 34.6 | O39: =IF(ISBLANK(I39),"N/A",IF(((I39-H39)*24)>INDEX(Dim_ServiceType!$E$2:$E$16,MATCH(E39,Dim_ServiceType!$A$2:$A$16,0)),"Yes","No")) -> No | P39: =IF(ISBLANK(H39),"Open (Unassigned)",IF(ISBLANK(I39),"In Progress",IF(ISBLANK(J39),"Resolved (Pending Closure)","Closed"))) -> Closed | Q39: 3 | R39: No
A40: 39 | B40: TCK-2025-00039 | C40: 2 | D40: 11 | E40: 7 | F40: 11 | G40: 45837.329 | H40: 45837.371 | I40: 45840.654 | J40: 45841.154 | K40: Call Center | L40: =IF(ISBLANK(H40),"",(H40-G40)*24) -> 1 | M40: =IF(ISBLANK(I40),"",(I40-H40)*24) -> 78.8 | N40: =IF(ISBLANK(J40),"",(J40-G40)*24) -> 91.8 | O40: =IF(ISBLANK(I40),"N/A",IF(((I40-H40)*24)>INDEX(Dim_ServiceType!$E$2:$E$16,MATCH(E40,Dim_ServiceType!$A$2:$A$16,0)),"Yes","No")) -> Yes | P40: =IF(ISBLANK(H40),"Open (Unassigned)",IF(ISBLANK(I40),"In Progress",IF(ISBLANK(J40),"Resolved (Pending Closure)","Closed"))) -> Closed | Q40: 4 | R40: No
A41: 40 | B41: TCK-2025-00040 | C41: 7 | D41: 12 | E41: 6 | F41: 6 | G41: 45693.635 | H41: 45693.885 | I41: 45695.018 | J41: 45695.185 | K41: Social Media | L41: =IF(ISBLANK(H41),"",(H41-G41)*24) -> 6 | M41: =IF(ISBLANK(I41),"",(I41-H41)*24) -> 27.2 | N41: =IF(ISBLANK(J41),"",(J41-G41)*24) -> 37.2 | O41: =IF(ISBLANK(I41),"N/A",IF(((I41-H41)*24)>INDEX(Dim_ServiceType!$E$2:$E$16,MATCH(E41,Dim_ServiceType!$A$2:$A$16,0)),"Yes","No")) -> No | P41: =IF(ISBLANK(H41),"Open (Unassigned)",IF(ISBLANK(I41),"In Progress",IF(ISBLANK(J41),"Resolved (Pending Closure)","Closed"))) -> Closed | Q41: 1 | R41: No
A42: 41 | B42: TCK-2025-00041 | C42: 6 | D42: 2 | E42: 4 | F42: 15 | G42: 45689.781 | H42: 45689.802 | I42: 45690.64 | J42: 45690.661 | K42: Mobile App | L42: =IF(ISBLANK(H42),"",(H42-G42)*24) -> 0.5 | M42: =IF(ISBLANK(I42),"",(I42-H42)*24) -> 20.1 | N42: =IF(ISBLANK(J42),"",(J42-G42)*24) -> 21.1 | O42: =IF(ISBLANK(I42),"N/A",IF(((I42-H42)*24)>INDEX(Dim_ServiceType!$E$2:$E$16,MATCH(E42,Dim_ServiceType!$A$2:$A$16,0)),"Yes","No")) -> No | P42: =IF(ISBLANK(H42),"Open (Unassigned)",IF(ISBLANK(I42),"In Progress",IF(ISBLANK(J42),"Resolved (Pending Closure)","Closed"))) -> Closed | Q42: 3 | R42: No
A43: 42 | B43: TCK-2025-00042 | C43: 10 | D43: 8 | E43: 12 | F43: 11 | G43: 45786.803 | H43: 45787.303 | I43: 45788.428 | J43: 45788.47 | K43: Mobile App | L43: =IF(ISBLANK(H43),"",(H43-G43)*24) -> 12 | M43: =IF(ISBLANK(I43),"",(I43-H43)*24) -> 27 | N43: =IF(ISBLANK(J43),"",(J43-G43)*24) -> 40 | O43: =IF(ISBLANK(I43),"N/A",IF(((I43-H43)*24)>INDEX(Dim_ServiceType!$E$2:$E$16,MATCH(E43,Dim_ServiceType!$A$2:$A$16,0)),"Yes","No")) -> Yes | P43: =IF(ISBLANK(H43),"Open (Unassigned)",IF(ISBLANK(I43),"In Progress",IF(ISBLANK(J43),"Resolved (Pending Closure)","Closed"))) -> Closed | Q43: 3 | R43: No
A44: 43 | B44: TCK-2025-00043 | C44: 7 | D44: 8 | E44: 11 | F44: 8 | G44: 45858.293 | H44: 45858.46 | I44: 45858.768 | J44: 45858.935 | K44: Retail Store | L44: =IF(ISBLANK(H44),"",(H44-G44)*24) -> 4 | M44: =IF(ISBLANK(I44),"",(I44-H44)*24) -> 7.4 | N44: =IF(ISBLANK(J44),"",(J44-G44)*24) -> 15.4 | O44: =IF(ISBLANK(I44),"N/A",IF(((I44-H44)*24)>INDEX(Dim_ServiceType!$E$2:$E$16,MATCH(E44,Dim_ServiceType!$A$2:$A$16,0)),"Yes","No")) -> No | P44: =IF(ISBLANK(H44),"Open (Unassigned)",IF(ISBLANK(I44),"In Progress",IF(ISBLANK(J44),"Resolved (Pending Closure)","Closed"))) -> Closed | Q44: 5 | R44: No
A45: 44 | B45: TCK-2025-00044 | C45: 12 | D45: 7 | E45: 6 | F45: 12 | G45: 45957.644 | H45: 45958.644 | I45: 45959.494 | J45: 45960.494 | K45: Website | L45: =IF(ISBLANK(H45),"",(H45-G45)*24) -> 24 | M45: =IF(ISBLANK(I45),"",(I45-H45)*24) -> 20.4 | N45: =IF(ISBLANK(J45),"",(J45-G45)*24) -> 68.4 | O45: =IF(ISBLANK(I45),"N/A",IF(((I45-H45)*24)>INDEX(Dim_ServiceType!$E$2:$E$16,MATCH(E45,Dim_ServiceType!$A$2:$A$16,0)),"Yes","No")) -> No | P45: =IF(ISBLANK(H45),"Open (Unassigned)",IF(ISBLANK(I45),"In Progress",IF(ISBLANK(J45),"Resolved (Pending Closure)","Closed"))) -> Closed | Q45: 5 | R45: No
A46: 45 | B46: TCK-2025-00045 | C46: 13 | D46: 12 | E46: 6 | F46: 4 | G46: 45925.843 | H46: 45925.926 | I46: 45928.293 | J46: 45928.543 | K46: Mobile App | L46: =IF(ISBLANK(H46),"",(H46-G46)*24) -> 2 | M46: =IF(ISBLANK(I46),"",(I46-H46)*24) -> 56.8 | N46: =IF(ISBLANK(J46),"",(J46-G46)*24) -> 64.8 | O46: =IF(ISBLANK(I46),"N/A",IF(((I46-H46)*24)>INDEX(Dim_ServiceType!$E$2:$E$16,MATCH(E46,Dim_ServiceType!$A$2:$A$16,0)),"Yes","No")) -> Yes | P46: =IF(ISBLANK(H46),"Open (Unassigned)",IF(ISBLANK(I46),"In Progress",IF(ISBLANK(J46),"Resolved (Pending Closure)","Closed"))) -> Closed | Q46: 5 | R46: No
A47: 46 | B47: TCK-2025-00046 | C47: 9 | D47: 14 | E47: 15 | F47: 9 | G47: 45757.62 | H47: 45757.787 | K47: Retail Store | L47: =IF(ISBLANK(H47),"",(H47-G47)*24) -> 4 | M47: =IF(ISBLANK(I47),"",(I47-H47)*24) | N47: =IF(ISBLANK(J47),"",(J47-G47)*24) | O47: =IF(ISBLANK(I47),"N/A",IF(((I47-H47)*24)>INDEX(Dim_ServiceType!$E$2:$E$16,MATCH(E47,Dim_ServiceType!$A$2:$A$16,0)),"Yes","No")) -> N/A | P47: =IF(ISBLANK(H47),"Open (Unassigned)",IF(ISBLANK(I47),"In Progress",IF(ISBLANK(J47),"Resolved (Pending Closure)","Closed"))) -> In Progress
A48: 47 | B48: TCK-2025-00047 | C48: 1 | D48: 7 | E48: 5 | F48: 9 | G48: 45769.962 | H48: 45770.462 | I48: 45770.97 | J48: 45771.137 | K48: Mobile App | L48: =IF(ISBLANK(H48),"",(H48-G48)*24) -> 12 | M48: =IF(ISBLANK(I48),"",(I48-H48)*24) -> 12.2 | N48: =IF(ISBLANK(J48),"",(J48-G48)*24) -> 28.2 | O48: =IF(ISBLANK(I48),"N/A",IF(((I48-H48)*24)>INDEX(Dim_ServiceType!$E$2:$E$16,MATCH(E48,Dim_ServiceType!$A$2:$A$16,0)),"Yes","No")) -> Yes | P48: =IF(ISBLANK(H48),"Open (Unassigned)",IF(ISBLANK(I48),"In Progress",IF(ISBLANK(J48),"Resolved (Pending Closure)","Closed"))) -> Closed | Q48: 3 | R48: Yes
A49: 48 | B49: TCK-2025-00048 | C49: 7 | D49: 15 | E49: 11 | F49: 10 | G49: 45796.413 | H49: 45796.434 | I49: 45796.905 | J49: 45797.072 | K49: Retail Store | L49: =IF(ISBLANK(H49),"",(H49-G49)*24) -> 0.5 | M49: =IF(ISBLANK(I49),"",(I49-H49)*24) -> 11.3 | N49: =IF(ISBLANK(J49),"",(J49-G49)*24) -> 15.8 | O49: =IF(ISBLANK(I49),"N/A",IF(((I49-H49)*24)>INDEX(Dim_ServiceType!$E$2:$E$16,MATCH(E49,Dim_ServiceType!$A$2:$A$16,0)),"Yes","No")) -> No | P49: =IF(ISBLANK(H49),"Open (Unassigned)",IF(ISBLANK(I49),"In Progress",IF(ISBLANK(J49),"Resolved (Pending Closure)","Closed"))) -> Closed | Q49: 4 | R49: No
A50: 49 | B50: TCK-2025-00049 | C50: 6 | D50: 13 | E50: 7 | F50: 9 | G50: 45916.916 | H50: 45916.958 | I50: 45917.516 | J50: 45918.016 | K50: Website | L50: =IF(ISBLANK(H50),"",(H50-G50)*24) -> 1 | M50: =IF(ISBLANK(I50),"",(I50-H50)*24) -> 13.4 | N50: =IF(ISBLANK(J50),"",(J50-G50)*24) -> 26.4 | O50: =IF(ISBLANK(I50),"N/A",IF(((I50-H50)*24)>INDEX(Dim_ServiceType!$E$2:$E$16,MATCH(E50,Dim_ServiceType!$A$2:$A$16,0)),"Yes","No")) -> No | P50: =IF(ISBLANK(H50),"Open (Unassigned)",IF(ISBLANK(I50),"In Progress",IF(ISBLANK(J50),"Resolved (Pending Closure)","Closed"))) -> Closed | Q50: 5 | R50: No
A51: 50 | B51: TCK-2025-00050 | C51: 5 | D51: 10 | E51: 1 | F51: 7 | G51: 45777.159 | H51: 45777.492 | I51: 45777.634 | J51: 45778.634 | K51: Retail Store | L51: =IF(ISBLANK(H51),"",(H51-G51)*24) -> 8 | M51: =IF(ISBLANK(I51),"",(I51-H51)*24) -> 3.4 | N51: =IF(ISBLANK(J51),"",(J51-G51)*24) -> 35.4 | O51: =IF(ISBLANK(I51),"N/A",IF(((I51-H51)*24)>INDEX(Dim_ServiceType!$E$2:$E$16,MATCH(E51,Dim_ServiceType!$A$2:$A$16,0)),"Yes","No")) -> No | P51: =IF(ISBLANK(H51),"Open (Unassigned)",IF(ISBLANK(I51),"In Progress",IF(ISBLANK(J51),"Resolved (Pending Closure)","Closed"))) -> Closed | Q51: 1 | R51: No
A52: 51 | B52: TCK-2025-00051 | C52: 2 | D52: 1 | E52: 8 | F52: 6 | G52: 45871.716 | H52: 45872.049 | K52: Website | L52: =IF(ISBLANK(H52),"",(H52-G52)*24) -> 8 | M52: =IF(ISBLANK(I52),"",(I52-H52)*24) | N52: =IF(ISBLANK(J52),"",(J52-G52)*24) | O52: =IF(ISBLANK(I52),"N/A",IF(((I52-H52)*24)>INDEX(Dim_ServiceType!$E$2:$E$16,MATCH(E52,Dim_ServiceType!$A$2:$A$16,0)),"Yes","No")) -> N/A | P52: =IF(ISBLANK(H52),"Open (Unassigned)",IF(ISBLANK(I52),"In Progress",IF(ISBLANK(J52),"Resolved (Pending Closure)","Closed"))) -> In Progress
A53: 52 | B53: TCK-2025-00052 | C53: 12 | D53: 3 | E53: 10 | F53: 11 | G53: 45923.815 | H53: 45924.815 | I53: 45925.09 | J53: 45925.257 | K53: Retail Store | L53: =IF(ISBLANK(H53),"",(H53-G53)*24) -> 24 | M53: =IF(ISBLANK(I53),"",(I53-H53)*24) -> 6.6 | N53: =IF(ISBLANK(J53),"",(J53-G53)*24) -> 34.6 | O53: =IF(ISBLANK(I53),"N/A",IF(((I53-H53)*24)>INDEX(Dim_ServiceType!$E$2:$E$16,MATCH(E53,Dim_ServiceType!$A$2:$A$16,0)),"Yes","No")) -> Yes | P53: =IF(ISBLANK(H53),"Open (Unassigned)",IF(ISBLANK(I53),"In Progress",IF(ISBLANK(J53),"Resolved (Pending Closure)","Closed"))) -> Closed | Q53: 3 | R53: No
...
